<mujoco model="robot_object">
  <include file="robot_2d.xml"/>

  <statistic center="0 0 0.1" extent="0.8"/>

  <visual>
    <headlight diffuse="0.6 0.6 0.6" ambient="0.3 0.3 0.3" specular="0 0 0"/>
    <rgba haze="0.15 0.25 0.35 1"/>
    <global azimuth="-130" elevation="-20"/>
  </visual>

  <asset>
    <texture type="skybox" builtin="gradient" rgb1="0.3 0.5 0.7" rgb2="0 0 0" width="512" height="3072"/>
    <texture type="2d" name="groundplane" builtin="checker" mark="edge" rgb1="0.2 0.3 0.4" rgb2="0.1 0.2 0.3"
      markrgb="0.8 0.8 0.8" width="300" height="300"/>
    <material name="groundplane" texture="groundplane" texuniform="true" texrepeat="5 5" reflectance="0.2"/>
  </asset>

  <worldbody>
    <!-- <light pos="0 0 1.5" dir="0 0 -1" directional="true"/>
    <geom name="floor" size="0 0 0.05" type="plane" material="groundplane"/> -->
    <body>
      <joint name="ob_x_joint" type="slide" axis="1 0 0" range="-10 10" />
      <joint name="ob_z_joint" type="slide" axis="0 0 1" range="-0.4 5" />
      <joint name="ob_pitch_joint" type="hinge" axis="0 1 0"/>
      <geom class="visual" name="object" type="box" size="0.3 0.3 0.02" pos="0 0 0" quat="1 0 0 0"/>
      <geom name="object_collision" type="box" size="0.3 0.3 0.02" pos="0 0 0" quat="1 0 0 0" friction="0.5 0.005 0.0001"/>
    </body>
  </worldbody>


</mujoco>