<mujoco model="hopper_model">
  <compiler angle="radian" meshdir="meshes" autolimits="true" />
  <option cone="elliptic" impratio="100" />
  
  <default>
    <default class="hopper">
      <geom friction="1.0" margin="0.001" condim="3"/>
      <joint damping="0.1" armature="0.01" frictionloss="0.2"/>
      <motor ctrlrange="-30 30"/>
      <default class="hip">
        <joint range="-0.6 1.5708"/>
      </default>
      <default class="knee">
        <joint range="-2.6 -1.3"/>
      </default>
      <default class="visual">
        <geom type="mesh" contype="0" conaffinity="0" group="2"/>
      </default>
      <default class="collision">
        <geom group="3"/>
      </default>
    </default>
  </default>

  <keyframe>
    <key name="0" qpos="0 0 0 0.9 -1.8" />
    <!-- <key name="0" qpos="0 0 0 0.9 -1.8 0 0 0 0 0 0 0 0 0 0 0 0 0 0" /> -->
  </keyframe>

  <worldbody>
    <body name="Base" pos="0 0 0.4" quat="1 0 0 0">
      <joint name="x_joint" type="slide" axis="1 0 0" range="-100 100" />
      <joint name="z_joint" type="slide" axis="0 0 1" range="-0.4 5" />
      <joint name="pitch_joint" type="hinge" axis="0 1 0"/>

      <body name="Torso" childclass="hopper">
        <geom class="visual" pos="0 0.013 0" type="mesh" mesh="torso_mesh" material="metal"/>
        <geom class="collision" pos="0 -0.0 0.06" quat="1 0 0 0" type="box" size="0.25 0.0115 0.0115"/>
        <inertial 
          pos="0.00012619 -0. 0.039743" 
          mass="2."
          diaginertia="0.001 0.04 0.04"
          />
        
        <site name="imu" pos="0 0 0" />
        
        <body name="Thigh" pos="0 -0. 0">
          <joint name="thigh_joint" class="hip" axis="0 1 0"/>
          <geom class="visual" pos="0 -0.013 0" type="mesh" mesh="thigh_mesh" material="metal"/>
          <geom class="collision" size="0.025 0.015 0.09" pos="-0.01 0. -0.07" type="box" />
          <inertial pos="0.0010373 0.013 -0.029921" mass="0.41602" diaginertia="0.0010413 0.001196 0.00021147"/>

          <!-- <body name="Coupler" pos="0 0 0" quat="1 0 0 0">
            <joint name="coupler_joint" axis="0 1 0" type="hinge"/>
            <geom type="mesh" mesh="Coupler" material="metal" class="visual"/>
          </body> -->
          
          <body name="Shank" pos="0 0. -0.22">
            <joint name="calf_joint" class="knee" axis="0 1 0"/>
            <geom class="visual" type="mesh" mesh="shank_mesh" material="metal"/>
            <geom class="collision" size="0.015 0.01 0.11" pos="0 0 -0.07" type="box" />
            <inertial pos="-0.000239033 0. -0.0752972" mass="0.116643" diaginertia="0.000594634 0.000591483 5.24161e-06"/>
            
            <body name="Foot" pos="0 0 -0.20193" quat="0.707105 0 0 -0.707108">
              <geom class="visual" type="mesh" mesh="foot_mesh" material="metal"/>
              <geom class="collision" size="0.015" pos="0 0 0" priority="1" condim="6"
              friction="1.0 0.02 0.01" euler="0 1.5708 0"/>
              <inertial 
                pos="5.2042E-18 0 -0.001849"
                mass="0.015263" 
                diaginertia="1.9449E-06 1.9397E-06 1.2829E-06"
                />

              <site name="foot_site" pos="0 0 0" size="0.015"/>
            </body>
          </body>
        </body>
      </body>
    </body>
  </worldbody>
<!-- 
  <equality>
    <joint joint1="coupler_joint" joint2="calf_joint"/>
  </equality> -->

  <actuator>
    <motor class="hip" name="thigh" joint="thigh_joint" />
    <motor class="knee" name="calf" joint="calf_joint" />
  </actuator>

  <sensor>
    <jointpos name="thigh_pos" joint="thigh_joint" noise="0.01"/>
    <jointpos name="calf_pos" joint="calf_joint" noise="0.01"/>

    <jointvel name="thigh_vel" joint="thigh_joint" noise="0.01"/>
    <jointvel name="calf_vel" joint="calf_joint" noise="0.01"/>

    <jointactuatorfrc name="thigh_torque" joint="thigh_joint" noise="0.01"/>
    <jointactuatorfrc name="calf_torque" joint="calf_joint" noise="0.01"/>

    <framequat name="imu_quat" objtype="site" objname="imu" noise="0.01"/>
    <gyro name="imu_gyro" site="imu" noise="0.01"/>
    <accelerometer name="imu_acc" site="imu" noise="0.01"/>
    
    <framepos name="frame_pos" objtype="site" objname="imu" noise="0.01"/>
    <framelinvel name="frame_vel" objtype="site" objname="imu" noise="0.01"/>

    <touch name="foot_force" site="foot_site" noise="0.01"/>
  </sensor>

  <asset>
    <material name="metal" rgba=".9 .95 .95 1" />
    <material name="black" rgba="0 0 0 1" />
    <material name="white" rgba="1 1 1 1" />
    <material name="gray" rgba="0.671705 0.692426 0.774270 1" />

    <mesh file="Torso.STL" name="torso_mesh" />
    <mesh file="Thigh.STL" name="thigh_mesh" />
    <mesh file="Shank.STL" name="shank_mesh" />
    <mesh file="Foot.STL" name="foot_mesh" />
    <mesh file="Coupler.STL" name="coupler_mesh" />
  </asset>

</mujoco>
