<?xml version="1.0" encoding="utf-8"?>
<!-- This URDF was automatically created by SolidWorks to URDF Exporter! Originally created by Stephen Brawner (brawner@gmail.com) 
     Commit Version: 1.6.0-4-g7f85cfe  Build Version: 1.6.7995.38578
     For more information, please see http://wiki.ros.org/sw_urdf_exporter -->
<robot
  name="PEA_leg_assem.SLDASM">
  <link
    name="Torso">
    <inertial>
      <origin
        xyz="-2.1048E-05 0.020151 0.015056"
        rpy="0 0 0" />
      <mass
        value="0.3612" />
      <inertia
        ixx="0.00017045"
        ixy="6.4163E-07"
        ixz="-1.2401E-08"
        iyy="0.00078888"
        iyz="1.0301E-06"
        izz="0.00092343" />
    </inertial>
    <visual>
      <origin
        xyz="0 0 0"
        rpy="0 0 0" />
      <geometry>
        <mesh
          filename="Torso.obj" />
      </geometry>
      <material
        name="">
        <color
          rgba="0.75294 0.75294 0.75294 1" />
      </material>
    </visual>
    <collision>
      <origin
        xyz="0 0 0"
        rpy="0 0 0" />
      <geometry>
        <mesh
          filename="Torso.obj" />
      </geometry>
    </collision>
  </link>
  <link
    name="Thigh">
    <inertial>
      <origin
        xyz="0.027216 -0.0025382 -0.0089058"
        rpy="0 0 0" />
      <mass
        value="0.43122" />
      <inertia
        ixx="0.00023052"
        ixy="-5.8304E-06"
        ixz="-4.9731E-06"
        iyy="0.0010696"
        iyz="1.4434E-06"
        izz="0.0012471" />
    </inertial>
    <visual>
      <origin
        xyz="0 0 0"
        rpy="0 0 0" />
      <geometry>
        <mesh
          filename="Thigh.obj" />
      </geometry>
      <material
        name="">
        <color
          rgba="0.75294 0.75294 0.75294 1" />
      </material>
    </visual>
    <collision>
      <origin
        xyz="0 0 0"
        rpy="0 0 0" />
      <geometry>
        <mesh
          filename="Thigh.obj" />
      </geometry>
    </collision>
  </link>
  <joint
    name="Hip"
    type="revolute">
    <origin
      xyz="0 0.026 0"
      rpy="-1.5708 -0.070972 3.1416" />
    <parent
      link="Torso" />
    <child
      link="Thigh" />
    <axis
      xyz="0 0 1" />
    <limit
      lower="0"
      upper="0"
      effort="0"
      velocity="0" />
  </joint>
  <link
    name="Shank">
    <inertial>
      <origin
        xyz="-0.013233 -0.012829 -0.073706"
        rpy="0 0 0" />
      <mass
        value="0.11665" />
      <inertia
        ixx="0.00030474"
        ixy="-2.0633E-08"
        ixz="-1.2207E-07"
        iyy="0.000294"
        iyz="-4.6853E-05"
        izz="1.2837E-05" />
    </inertial>
    <visual>
      <origin
        xyz="0 0 0"
        rpy="0 0 0" />
      <geometry>
        <mesh
          filename="Shank.obj" />
      </geometry>
      <material
        name="">
        <color
          rgba="0.75294 0.75294 0.75294 1" />
      </material>
    </visual>
    <collision>
      <origin
        xyz="0 0 0"
        rpy="0 0 0" />
      <geometry>
        <mesh
          filename="Shank.obj" />
      </geometry>
    </collision>
  </link>
  <joint
    name="Knee"
    type="continuous">
    <origin
      xyz="0.22 0 0"
      rpy="1.5572 1.5708 0" />
    <parent
      link="Thigh" />
    <child
      link="Shank" />
    <axis
      xyz="1 0 0" />
  </joint>
</robot>
