<mujoco model="PEA_leg_assem.SLDASM">
  <compiler angle="radian"/>
  <asset>
    <mesh name="Torso" file="Torso.obj"/>
    <mesh name="Thigh" file="Thigh.obj"/>
    <mesh name="Shank" file="Shank.obj"/>
  </asset>
  <worldbody>
    <geom type="mesh" rgba="0.75294 0.75294 0.75294 1" mesh="Torso"/>
    <body name="Thigh" pos="0 0.026 0" quat="0.0250846 0.0250897 -0.706663 0.70666">
      <inertial pos="0.027216 -0.0025382 -0.0089058" quat="0.000491445 0.705358 0.00538399 0.70883" mass="0.43122" diaginertia="0.00124714 0.00106963 0.000230455"/>
      <joint name="Hip" pos="0 0 0" axis="0 0 1"/>
      <geom type="mesh" rgba="0.75294 0.75294 0.75294 1" mesh="Thigh"/>
      <body name="Shank" pos="0.22 0 0" quat="0.503387 0.496588 0.503388 -0.49659">
        <inertial pos="-0.013233 -0.012829 -0.073706" quat="0.996768 -0.080339 0.000195557 -0.000146218" mass="0.11665" diaginertia="0.00030474 0.000301602 5.23491e-06"/>
        <joint name="Knee" pos="0 0 0" axis="1 0 0"/>
        <geom type="mesh" rgba="0.75294 0.75294 0.75294 1" mesh="Shank"/>
      </body>
    </body>
  </worldbody>
</mujoco>
